<?xml version="1.0" encoding="UTF-8"?>
<!-- Generated by org.testng.reporters.JUnitReportReporter -->
<testsuite hostname="SSTANCQCLAB16VM" name="tests.UsingAssertions" tests="1" failures="0" timestamp="8 Oct 2015 01:52:03 GMT" time="0.012" errors="1">
  <testcase name="testGoogleSearch" time="0.012" classname="tests.UsingAssertions">
    <error type="java.lang.AssertionError" message="Error coming because of xyz reason expected:&lt;true&gt; but was:&lt;false&gt;">
      <![CDATA[java.lang.AssertionError: Error coming because of xyz reason expected:<true> but was:<false>
	at org.testng.Assert.fail(Assert.java:89)
	at org.testng.Assert.failNotEquals(Assert.java:480)
	at org.testng.Assert.assertTrue(Assert.java:37)
	at tests.UsingAssertions.testGoogleSearch(UsingAssertions.java:25)
	at sun.reflect.NativeMethodAccessorImpl.invoke0(Native Method)
	at sun.reflect.NativeMethodAccessorImpl.invoke(NativeMethodAccessorImpl.java:57)
	at sun.reflect.DelegatingMethodAccessorImpl.invoke(DelegatingMethodAccessorImpl.java:43)
	at java.lang.reflect.Method.invoke(Method.java:601)
	at org.testng.internal.MethodInvocationHelper.invokeMethod(MethodInvocationHelper.java:76)
	at org.testng.internal.Invoker.invokeMethod(Invoker.java:673)
	at org.testng.internal.Invoker.invokeTestMethod(Invoker.java:846)
	at org.testng.internal.Invoker.invokeTestMethods(Invoker.java:1170)
	at org.testng.internal.TestMethodWorker.invokeTestMethods(TestMethodWorker.java:125)
	at org.testng.internal.TestMethodWorker.run(TestMethodWorker.java:109)
	at org.testng.TestRunner.runWorkers(TestRunner.java:1147)
	at org.testng.TestRunner.privateRun(TestRunner.java:749)
	at org.testng.TestRunner.run(TestRunner.java:600)
	at org.testng.SuiteRunner.runTest(SuiteRunner.java:317)
	at org.testng.SuiteRunner.runSequentially(SuiteRunner.java:312)
	at org.testng.SuiteRunner.privateRun(SuiteRunner.java:274)
	at org.testng.SuiteRunner.run(SuiteRunner.java:223)
	at org.testng.SuiteRunnerWorker.runSuite(SuiteRunnerWorker.java:52)
	at org.testng.SuiteRunnerWorker.run(SuiteRunnerWorker.java:86)
	at org.testng.TestNG.runSuitesSequentially(TestNG.java:1039)
	at org.testng.TestNG.runSuitesLocally(TestNG.java:964)
	at org.testng.TestNG.run(TestNG.java:900)
	at org.testng.TestNG.privateMain(TestNG.java:1182)
	at org.testng.TestNG.main(TestNG.java:1146)
]]>
    </error>
  </testcase>
</testsuite>
